<?xml version="1.0" encoding="utf-8"?>
<!-- This URDF was automatically created by SolidWorks to URDF Exporter! Originally created by Stephen Brawner (brawner@gmail.com) 
     Commit Version: 1.5.1-0-g916b5db  Build Version: 1.5.7152.31018
     For more information, please see http://wiki.ros.org/sw_urdf_exporter -->
<robot
  name="arm_new">
  <link
    name="base_link">
    <inertial>
      <origin
        xyz="0.010367 -4.8905E-08 0.032724"
        rpy="0 0 0" />
      <mass
        value="0.7864" />
      <inertia
        ixx="0.00089549"
        ixy="-1.7657E-09"
        ixz="6.0141E-05"
        iyy="0.0015207"
        iyz="6.3216E-10"
        izz="0.0017142" />
    </inertial>
    <visual>
      <origin
        xyz="0 0 0"
        rpy="0 0 0" />
      <geometry>
        <mesh
          filename="package://arm_new/meshes/base_link.STL" />
      </geometry>
      <material
        name="">
        <color
          rgba="0.7451 0.7451 0.7451 1" />
      </material>
    </visual>
    <collision>
      <origin
        xyz="0 0 0"
        rpy="0 0 0" />
      <geometry>
        <mesh
          filename="package://arm_new/meshes/base_link.STL" />
      </geometry>
    </collision>
  </link>
  <link
    name="Link1">
    <inertial>
      <origin
        xyz="0.016587 -4.9988E-05 -0.18666"
        rpy="0 0 0" />
      <mass
        value="0.12176" />
      <inertia
        ixx="7.3849E-05"
        ixy="-1.5322E-11"
        ixz="3.0283E-05"
        iyy="9.5654E-05"
        iyz="2.3554E-11"
        izz="5.1643E-05" />
    </inertial>
    <visual>
      <origin
        xyz="0 0 0"
        rpy="0 0 0" />
      <geometry>
        <mesh
          filename="package://arm_new/meshes/Link1.STL" />
      </geometry>
      <material
        name="">
        <color
          rgba="0.7451 0.7451 0.7451 1" />
      </material>
    </visual>
    <collision>
      <origin
        xyz="0 0 0"
        rpy="0 0 0" />
      <geometry>
        <mesh
          filename="package://arm_new/meshes/Link1.STL" />
      </geometry>
    </collision>
  </link>
  <joint
    name="Joint1"
    type="revolute">
    <origin
      xyz="0.037707 -5E-05 0.29937"
      rpy="0 0 -3.1416" />
    <parent
      link="base_link" />
    <child
      link="Link1" />
    <axis
      xyz="0 0 -1" />
    <limit
      lower="0"
      upper="6.28"
      effort="0"
      velocity="0" />
  </joint>
  <link
    name="Link2">
    <inertial>
      <origin
        xyz="-0.00054103 5.5678E-05 0.041539"
        rpy="0 0 0" />
      <mass
        value="0.16406" />
      <inertia
        ixx="0.00021226"
        ixy="-4.936E-09"
        ixz="-1.389E-06"
        iyy="0.00017369"
        iyz="3.7944E-07"
        izz="7.7824E-05" />
    </inertial>
    <visual>
      <origin
        xyz="0 0 0"
        rpy="0 0 0" />
      <geometry>
        <mesh
          filename="package://arm_new/meshes/Link2.STL" />
      </geometry>
      <material
        name="">
        <color
          rgba="0.7451 0.7451 0.7451 1" />
      </material>
    </visual>
    <collision>
      <origin
        xyz="0 0 0"
        rpy="0 0 0" />
      <geometry>
        <mesh
          filename="package://arm_new/meshes/Link2.STL" />
      </geometry>
    </collision>
  </link>
  <joint
    name="Joint2"
    type="revolute">
    <origin
      xyz="0 -5E-05 -0.1582"
      rpy="0 0 3.1416" />
    <parent
      link="Link1" />
    <child
      link="Link2" />
    <axis
      xyz="0 1 0" />
    <limit
      lower="0"
      upper="6.28"
      effort="0"
      velocity="0" />
  </joint>
  <link
    name="Link3">
    <inertial>
      <origin
        xyz="0.0029219 -6.8536E-05 0.033181"
        rpy="0 0 0" />
      <mass
        value="0.13328" />
      <inertia
        ixx="0.00010361"
        ixy="-2.6695E-08"
        ixz="-3.1074E-06"
        iyy="8.3611E-05"
        iyz="-3.0309E-07"
        izz="6.3714E-05" />
    </inertial>
    <visual>
      <origin
        xyz="0 0 0"
        rpy="0 0 0" />
      <geometry>
        <mesh
          filename="package://arm_new/meshes/Link3.STL" />
      </geometry>
      <material
        name="">
        <color
          rgba="0.7451 0.7451 0.7451 1" />
      </material>
    </visual>
    <collision>
      <origin
        xyz="0 0 0"
        rpy="0 0 0" />
      <geometry>
        <mesh
          filename="package://arm_new/meshes/Link3.STL" />
      </geometry>
    </collision>
  </link>
  <joint
    name="Joint3"
    type="revolute">
    <origin
      xyz="0 -5E-05 0.087"
      rpy="0 0 0" />
    <parent
      link="Link2" />
    <child
      link="Link3" />
    <axis
      xyz="0 1 0" />
    <limit
      lower="0"
      upper="6.28"
      effort="0"
      velocity="0" />
  </joint>
  <link
    name="Link4">
    <inertial>
      <origin
        xyz="-6.93889390390723E-18 1.60733060162403E-13 0.0230502436889771"
        rpy="0 0 0" />
      <mass
        value="0.0616446065967099" />
      <inertia
        ixx="2.35629768781271E-05"
        ixy="2.06327010680198E-10"
        ixz="4.93789336541773E-22"
        iyy="2.16264848632999E-05"
        iyz="-2.66653461902765E-16"
        izz="1.4527300665041E-05" />
    </inertial>
    <visual>
      <origin
        xyz="0 0 0"
        rpy="0 0 0" />
      <geometry>
        <mesh
          filename="package://arm_new/meshes/Link4.STL" />
      </geometry>
      <material
        name="">
        <color
          rgba="0.745098039215686 0.745098039215686 0.745098039215686 1" />
      </material>
    </visual>
    <collision>
      <origin
        xyz="0 0 0"
        rpy="0 0 0" />
      <geometry>
        <mesh
          filename="package://arm_new/meshes/Link4.STL" />
      </geometry>
    </collision>
  </link>
  <joint
    name="Joint4"
    type="revolute">
    <origin
      xyz="0 0 0.0712"
      rpy="0 0 -3.1416" />
    <parent
      link="Link3" />
    <child
      link="Link4" />
    <axis
      xyz="0 0 1" />
    <limit
      lower="0"
      upper="6.28"
      effort="0"
      velocity="0" />
  </joint>
  <link
    name="Link5">
    <inertial>
      <origin
        xyz="-0.00540369889878293 0.000111388474332554 0.0298563406822311"
        rpy="0 0 0" />
      <mass
        value="0.082003985184141" />
      <inertia
        ixx="4.25538356064228E-05"
        ixy="-4.93618679407722E-08"
        ixz="3.44134827995119E-06"
        iyy="3.79923819156701E-05"
        iyz="2.72721651106619E-07"
        izz="3.14025133057499E-05" />
    </inertial>
    <visual>
      <origin
        xyz="0 0 0"
        rpy="0 0 0" />
      <geometry>
        <mesh
          filename="package://arm_new/meshes/Link5.STL" />
      </geometry>
      <material
        name="">
        <color
          rgba="0.745098039215686 0.745098039215686 0.745098039215686 1" />
      </material>
    </visual>
    <collision>
      <origin
        xyz="0 0 0"
        rpy="0 0 0" />
      <geometry>
        <mesh
          filename="package://arm_new/meshes/Link5.STL" />
      </geometry>
    </collision>
  </link>
  <joint
    name="Joint5"
    type="revolute">
    <origin
      xyz="0 0 0.0415"
      rpy="0 0 3.1416" />
    <parent
      link="Link4" />
    <child
      link="Link5" />
    <axis
      xyz="0 1 0" />
    <limit
      lower="0"
      upper="6.28"
      effort="0"
      velocity="0" />
  </joint>
  <link
    name="EE">
    <inertial>
      <origin
        xyz="0.042146146986961 -4.95936236896049E-09 0.0778740689030945"
        rpy="0 0 0" />
      <mass
        value="1.07322722870269" />
      <inertia
        ixx="0.00185339937127512"
        ixy="-5.12364747030885E-09"
        ixz="-5.92986358897838E-05"
        iyy="0.00219441701048786"
        iyz="-3.14292637714027E-10"
        izz="0.00211751149042562" />
    </inertial>
    <visual>
      <origin
        xyz="0 0 0"
        rpy="0 0 0" />
      <geometry>
        <mesh
          filename="package://arm_new/meshes/EE.STL" />
      </geometry>
      <material
        name="">
        <color
          rgba="0.745098039215686 0.745098039215686 0.745098039215686 1" />
      </material>
    </visual>
    <collision>
      <origin
        xyz="0 0 0"
        rpy="0 0 0" />
      <geometry>
        <mesh
          filename="package://arm_new/meshes/EE.STL" />
      </geometry>
    </collision>
  </link>
  <joint
    name="Joint6"
    type="revolute">
    <origin
      xyz="0 0 0.05975"
      rpy="0 0 0" />
    <parent
      link="Link5" />
    <child
      link="EE" />
    <axis
      xyz="0 0 1" />
    <limit
      lower="0"
      upper="6.28"
      effort="0"
      velocity="0" />
  </joint>
</robot>